**You:**

File "/Users/yutianran/opt/anaconda3/lib/python3.9/site-packages/mysql/connector/abstracts.py", line 1211, in reconnect raise InterfaceError(msg) from err mysql.connector.errors.InterfaceError: Can not reconnect to MySQL after 1 attempt(s): Unread result found

* * *

**ChatGPT:**

This error message indicates that there was an attempt to reconnect to a MySQL database, but the attempt failed because an unread result was found. This means that there is still data that was returned from the database that has not been processed yet.

To resolve this error, you should first make sure that any existing queries or transactions are completed before attempting to reconnect to the database. You may also need to check for any unclosed database connections or cursors.

You can try closing all connections and cursors using the `close()` method, and then attempt to reconnect to the database. If this does not work, you may need to investigate the root cause of the issue by examining your code and database queries to identify any potential issues. It is also possible that there may be a problem with the MySQL server itself, so you may need to consult the MySQL documentation or seek assistance from a MySQL expert.

* * *

**You:**

说中文

* * *

**ChatGPT:**

这个错误信息表示尝试重新连接到 MySQL 数据库时失败了，因为发现了一个未读取的结果。这意味着仍然有数据从数据库返回但尚未被处理。

为了解决这个错误，首先需要确保任何现有的查询或事务已经完成，然后再尝试重新连接到数据库。您可能还需要检查是否有未关闭的数据库连接或游标。

您可以尝试使用 `close()` 方法关闭所有连接和游标，然后尝试重新连接到数据库。如果这样仍然不起作用，您可能需要检查代码和数据库查询的根本原因，以确定是否存在潜在的问题。也有可能 MySQL 服务器本身存在问题，因此您可能需要查阅 MySQL 文档或寻求 MySQL 专家的帮助。

* * *

**You:**

File "/Users/yutianran/opt/anaconda3/lib/python3.9/site-packages/mysql/connector/connection.py", line 1321, in reset\_session raise OperationalError("MySQL Connection not available.") mysql.connector.errors.OperationalError: MySQL Connection not available.

* * *

**ChatGPT:**

这个错误信息表示尝试重置 MySQL 连接的会话时出现了问题，因为 MySQL 连接不可用。

通常，这个错误可能是由以下几个原因造成的：

1.  MySQL 服务器已关闭或不可用
2.  网络连接问题，导致无法连接到 MySQL 服务器
3.  MySQL 连接池达到了最大连接数，无法建立新的连接
4.  数据库用户权限不足，无法连接到数据库
5.  数据库配置错误，如端口号、主机名、用户名、密码等

要解决这个问题，您可以尝试以下几个步骤：

1.  检查 MySQL 服务器是否正在运行，并且网络连接是否正常
2.  确保您使用的数据库用户名和密码是正确的，并且具有连接到数据库的权限
3.  检查连接池的最大连接数是否已经达到，如果达到了，可以增加最大连接数或者释放一些连接
4.  确认 MySQL 连接配置是否正确，特别是主机名、端口号、用户名和密码是否正确

如果您已经排除了以上问题，但仍然遇到此错误，请检查您的代码，以确定是否存在其他问题或异常情况。

* * *

**You:**

Traceback (most recent call last): File "/Users/yutianran/MyGithub/MyCode/test/check\_url.py", line 73, in get\_bookmarks bookmarks.append(bookmark) File "/Users/yutianran/opt/anaconda3/lib/python3.9/site-packages/mysql/connector/abstracts.py", line 1519, in \_\_exit\_\_ self.close() File "/Users/yutianran/opt/anaconda3/lib/python3.9/site-packages/mysql/connector/cursor.py", line 427, in close self.\_connection.handle\_unread\_result() File "/Users/yutianran/opt/anaconda3/lib/python3.9/site-packages/mysql/connector/connection.py", line 1711, in handle\_unread\_result raise InternalError("Unread result found") mysql.connector.errors.InternalError: Unread result found

* * *

**ChatGPT:**

这个错误信息表示在 MySQL 连接中发现了一个未读的结果。这通常是由于在使用游标执行查询时，没有将所有结果读取完全导致的。

要解决这个问题，您可以尝试以下几个步骤：

1.  确保在使用游标执行查询时，将所有结果读取完全。例如，使用 `fetchall()` 方法将所有结果读取到一个列表中，然后关闭游标。
2.  确保在使用完游标后及时关闭游标。可以使用 `close()` 方法关闭游标，以便将其返回到连接池中。
3.  检查代码中是否有其他未处理的查询结果。如果在查询中使用了多个游标，则必须确保使用完一个游标后再使用另一个游标。

如果您已经排除了以上问题，但仍然遇到此错误，请检查您的代码和查询，以确定是否存在其他问题或异常情况。此外，您还可以尝试使用 MySQL 客户端手动执行相同的查询，以检查是否存在类似的问题。

* * *

**You:**

\# 根据title查询书签信息 @app.route("/bookmarks", methods=\["GET"\]) def get\_bookmarks(): title = request.args.get("title", "") print(f"get\_bookmarks title: {title}") bookmarks = \[\] with connection\_pool.get\_connection() as connection: with connection.cursor() as cursor: query = "SELECT \* FROM bookmarks WHERE title LIKE %s" cursor.execute(query, ("%" + title + "%",)) result = cursor.fetchall() for item in result: bookmark = {"id": item\["id"\], "title": item\["title"\], "url": item\["url"\]} bookmarks.append(bookmark) return resp(0, "查询成功", bookmarks) 报错： bookmark = {"id": item\["id"\], "title": item\["title"\], "url": item\["url"\]} TypeError: tuple indices must be integers or slices, not str

* * *

**ChatGPT:**

这个错误表示您尝试使用字符串作为元组的索引，而不是整数或切片。在这里，`cursor.fetchall()` 方法返回的是一个包含元组的列表，其中元组的每个元素对应查询结果中的一列。

解决这个问题，您需要使用整数索引来访问元组中的元素。例如，将您的代码改为以下形式：

```go
for item in result:
    bookmark = {"id": item[0], "title": item[1], "url": item[2]}
    bookmarks.append(bookmark)
```

在这个例子中，`item[0]` 对应查询结果中的第一列，`item[1]` 对应第二列，`item[2]` 对应第三列。您可以按照自己的查询结果的列顺序来访问元组中的元素。

另外，您还可以考虑使用 `cursor.fetchall()` 方法返回的每个元组转换为一个命名元组或字典对象，以便更好地访问和处理查询结果中的列数据。例如，可以将每个元组转换为一个命名元组：

```makefile
from collections import namedtuple

# 定义一个命名元组，包含 id、title 和 url 三个字段
Bookmark = namedtuple("Bookmark", ["id", "title", "url"])

# 将查询结果中的每个元组转换为一个命名元组
result = [Bookmark(*item) for item in cursor.fetchall()]

# 将命名元组转换为字典列表
bookmarks = [item._asdict() for item in result]
```

这样可以更方便地访问和处理查询结果中的列数据。